Traceback (most recent call last):
  File "main.py", line 125, in <module>
    main()
  File "main.py", line 47, in main
    print(config.id)
  File "/DATA2/USERS/allen/anaconda3/envs/LISA_env/lib/python3.6/site-packages/wandb/wandb_config.py", line 256, in __getattr__
    return self.__getitem__(key)
  File "/DATA2/USERS/allen/anaconda3/envs/LISA_env/lib/python3.6/site-packages/wandb/wandb_config.py", line 246, in __getitem__
    return self._items[key]
KeyError: 'id'
